Workbook

Sheet Patient_Log
A1: Date | B1: Unit | C1: Visit_Window | D1: Room | E1: Available | F1: Interaction_Time_Min | G1: Notes | H1: Reason
A2: 2026-08-06 | B2: 3 West | C2: 8:00 AM | E2: Yes | F2: 4
A3: 2026-08-06 | B3: 3 West | C3: 8:00 AM | E3: Yes | F3: 4
A4: 2026-08-06 | B4: 3 West | C4: 8:00 AM | E4: Yes | F4: 4
A5: 2026-08-06 | B5: 3 West | C5: 8:00 AM | E5: Yes | F5: 5
A6: 2026-08-06 | B6: 2 East | C6: 8:00 AM | E6: Yes | F6: 6
A7: 2026-08-06 | B7: 2 East | C7: 8:00 AM | E7: Yes | F7: 6
A8: 2026-08-06 | B8: 2 East | C8: 8:00 AM | E8: Yes | F8: 6
A9: 2026-08-06 | B9: 2 East | C9: 8:00 AM | E9: Yes | F9: 6
A10: 2026-08-06 | B10: 2 East | C10: 8:00 AM | E10: Yes | F10: 6
A11: 2026-08-06 | B11: 2 East | C11: 8:00 AM | E11: Yes | F11: 9.28
A12: 2026-08-06 | B12: 3 West | C12: 11:00 AM | E12: Yes | F12: 4
A13: 2026-08-06 | B13: 3 West | C13: 11:00 AM | E13: Yes | F13: 4
A14: 2026-08-06 | B14: 3 West | C14: 11:00 AM | E14: No | G14: Was not tracking "Reason" at this time. | H14: Other
A15: 2026-08-06 | B15: 2 East | C15: 11:00 AM | E15: No | G15: Was not tracking "Reason" at this time. | H15: Other
A16: 2026-08-06 | B16: 3 West | C16: 2:30 PM | D16: 24 | E16: Yes | F16: 5.58
A17: 2026-08-06 | B17: 3 West | C17: 2:30 PM | D17: 26 | E17: Yes | F17: 3.08
A18: 2026-08-06 | B18: 3 West | C18: 2:30 PM | D18: 25 | E18: No | G18: Was not tracking "Reason" at this time. | H18: Other
A19: 2026-08-06 | B19: 2 East | C19: 2:30 PM | D19: 01 | E19: Yes | F19: 12.74 | G19: Took long bc I collected Likes and Dislikes
A20: 2026-08-07 | B20: 3 West | C20: 8:00 AM | D20: 26 | E20: Yes | F20: 6
A21: 2026-08-07 | B21: 3 West | C21: 8:00 AM | D21: 17 | E21: Yes | F21: 6
A22: 2026-08-07 | B22: 3 West | C22: 8:00 AM | D22: 35 | E22: No | G22: Was not tracking "Reason" at this time. | H22: Other
A23: 2026-08-07 | B23: 3 West | C23: 2:30 PM | D23: 6 | E23: Yes | F23: 10
A24: 2026-08-07 | B24: 3 West | C24: 2:30 PM | D24: 25 | E24: No | G24: Transfer to Tele | H24: Discharged/Transferred
A25: 2026-08-07 | B25: 2 East | C25: 2:30 PM | D25: 01 | E25: No | G25: Discharged | H25: Discharged/Transferred
A26: 2026-08-07 | B26: 2 East | C26: 2:30 PM | D26: 18 | E26: Yes | F26: 13.45
A27: 2026-08-07 | B27: 2 East | C27: 2:30 PM | D27: 28 | E27: Yes | F27: 12.36
A28: 2026-08-07 | B28: 3 West | C28: 2:30 PM | D28: 35 | E28: Yes | F28: 8.37
A29: 2026-08-10 | B29: 3 West | C29: 11:00 AM | D29: 05 | E29: Yes | F29: 13.87
A30: 2026-08-10 | B30: 3 West | C30: 11:00 AM | D30: 06 | E30: Yes | F30: 12.53
A31: 2026-08-10 | B31: 3 West | C31: 11:00 AM | D31: 29 | E31: Yes | F31: 5.29
A32: 2026-08-10 | B32: 3 West | C32: 11:00 AM | D32: 17 | E32: No
A33: 2026-08-10 | B33: 2 East | C33: 11:00 AM | D33: 28 | E33: Yes | F33: 8.25
A34: 2026-08-11 | B34: 3 West | C34: 8:00 AM | D34: 04 | E34: Yes | F34: 3.66
A35: 2026-08-11 | B35: 3 West | C35: 8:00 AM | D35: 05 | E35: Yes | F35: 9.04
A36: 2026-08-11 | B36: 3 West | C36: 8:00 AM | D36: 09 | E36: Yes | F36: 0.04 | G36: refused okay w/ w/e
A37: 2026-08-11 | B37: 3 West | C37: 8:00 AM | D37: 29 | E37: Yes | F37: 1.96
A38: 2026-08-11 | B38: 2 East | C38: 8:00 AM | D38: 28 | E38: No | G38: expects to DC today | H38: Discharged/Transferred
A39: 2026-08-11 | B39: 2 East | C39: 8:00 AM | D39: 11 | E39: No | G39: Dr rounding | H39: With Provider
A40: 2026-08-11 | B40: 2 East | C40: 8:00 AM | D40: 18 | E40: No | G40: Dr rounding | H40: With Provider
...

Sheet Unit_Log
A1: Date | B1: Unit | C1: Visit_Window | D1: Patients_Attempted | E1: Patients_Seen | F1: Patients_Unavailable | G1: Session_Duration_Min
A2: 2026-07-29 | D2: 12 | E2: 8 | F2: =IFERROR(D2-E2,0) -> 4 | G2: 70
A3: 2026-07-30 | D3: 8 | E3: 8 | F3: =IFERROR(D3-E3,0) -> 0
A4: 2026-07-31 | D4: 8 | E4: 8 | F4: =IFERROR(D4-E4,0) -> 0
A5: 2026-08-03 | D5: 9 | E5: 9 | F5: =IFERROR(D5-E5,0) -> 0
A6: 2026-08-04 | D6: 9 | E6: 8 | F6: =IFERROR(D6-E6,0) -> 1
A7: 2026-08-05 | D7: 8 | E7: 8 | F7: =IFERROR(D7-E7,0) -> 0
A8: 2026-08-06 | B8: 3 West | C8: 8:00 AM | D8: 4 | E8: 4 | F8: =IFERROR(D8-E8,0) -> 0 | G8: 17
A9: 2026-08-06 | B9: 2 East | C9: 8:00 AM | D9: 6 | E9: 6 | F9: =IFERROR(D9-E9,0) -> 0 | G9: 39
A10: 2026-08-06 | B10: 3 West | C10: 11:00 AM | D10: 2 | E10: 1 | F10: =IFERROR(D10-E10,0) -> 1 | G10: 9
A11: 2026-08-06 | B11: 2 East | C11: 11:00 AM | D11: 1 | E11: 0 | F11: =IFERROR(D11-E11,0) -> 1 | G11: 1
A12: 2026-08-06 | B12: 3 West | C12: 2:30 PM | D12: 3 | E12: 2 | F12: =IFERROR(D12-E12,0) -> 1
A13: 2026-08-06 | B13: 2 East | C13: 2:30 PM | D13: 1 | E13: 1 | F13: =IFERROR(D13-E13,0) -> 0 | G13: 13
A14: 2026-08-07 | B14: 3 West | C14: 8:00 AM | D14: 3 | E14: 2 | F14: =IFERROR(D14-E14,0) -> 1
A15: 2026-08-07 | B15: 3 West | C15: 2:30 PM | D15: 3 | E15: 2 | F15: =IFERROR(D15-E15,0) -> 1
A16: 2026-08-07 | B16: 2 East | C16: 2:30 PM | D16: 3 | E16: 2 | F16: 1
A17: 2026-08-10 | B17: 3 West | C17: 11:00 AM | D17: 4 | E17: 3 | F17: =IFERROR(D17-E17,0) -> 1 | G17: 37
A18: 2026-08-10 | B18: 2 East | C18: 11:00 AM | D18: 1 | E18: 1 | F18: =IFERROR(D18-E18,0) -> 0 | G18: 8
A19: 2026-08-11 | B19: 3 West | C19: 8:00 AM | D19: 4 | E19: 4 | F19: =IFERROR(D19-E19,0) -> 0 | G19: 20
A20: 2026-08-11 | B20: 2 East | C20: 8:00 AM | D20: 3 | E20: 0 | F20: =IFERROR(D20-E20,0) -> 3 | G20: 2
A21: 2026-08-12 | B21: 3 West | C21: 11:00 AM | D21: 3 | E21: 3 | F21: 0 | G21: 42.62
A22: 2026-08-12 | B22: 3 West | C22: 2:30 PM | D22: 2 | E22: 2 | F22: 0 | G22: 19.12
A23: 2026-08-12 | B23: 2 East | C23: 2:30 PM | D23: 4 | E23: 2 | F23: 2 | G23: 11.43
A24: 2026-08-13 | B24: 3 West | C24: 2:30 PM | D24: 4 | E24: 2 | F24: 2 | G24: 19.03
A25: 2026-08-13 | B25: 2 East | C25: 2:30 PM | D25: 5 | E25: 1 | F25: 4 | G25: 10.49
A26: 2026-08-14 | B26: 3 West | C26: 2:30 PM | D26: 3 | E26: 1 | F26: 2 | G26: 5.24
A27: 2026-08-14 | B27: 2 East | C27: 2:30 PM | D27: 2 | E27: 2 | F27: 0 | G27: 28.65
A28: 2026-08-17 | B28: 3 West | C28: 2:30 PM | D28: 8 | E28: 7 | F28: 1 | G28: 43.78
A29: 2026-08-17 | B29: 2 East | C29: 2:30 PM | D29: 2 | E29: 2 | F29: 0 | G29: 14.24
A30: 2026-08-19 | B30: 3 West | C30: 2:30 PM | D30: 8 | E30: 8 | F30: 0 | G30: 45.85
A31: 2026-08-20 | B31: 3 West | C31: 2:30 PM | D31: 5 | E31: 3 | F31: 2 | G31: 9.78
A32: 2026-08-20 | B32: 2 East | C32: 2:30 PM | D32: 5 | E32: 5 | F32: 0 | G32: 19.78
... A122: 2026-09-29 | B122: 3 West | C122: 2:00 PM | D122: 1 | E122: 1 | F122: 0 | G122: 8
A123: 2026-09-30 | B123: 2 East | C123: 12:30 PM | D123: 2 | E123: 2 | F123: 0 | G123: 24.76
A124: 2026-09-30 | B124: 3 West | C124: 12:30 PM | D124: 2 | E124: 2 | F124: 0 | G124: 17.86
A125: 2026-09-30 | B125: ICU | C125: 12:30 PM | D125: 2 | E125: 2 | F125: 0 | G125: 19.81
A126: 46296 | B126: 3 West | C126: 6:30 PM | D126: 7 | E126: 4 | F126: 3 | G126: 21.56
A127: 46296 | B127: ICU | C127: 6:30 PM | D127: 1 | E127: 1 | F127: 0 | G127: 12.24
A128: 46296 | B128: 2 East | C128: 6:30 PM | D128: 1 | E128: 1 | F128: 0 | G128: 2.17
A129: 46297 | B129: 2 East | C129: 3:30 PM | D129: 1 | E129: 0 | F129: 1 | G129: 1.42
...

Sheet Summary
A1: SELECT MENU — SUMMARY
A2: Auto-updates as new rows are added to the Patient Log sheet.
A4: Patient Interaction Times | B4: Minutes
A5: Minimum Interaction Time | B5: {=MIN(IF(Patient_Log!F16:F1024>=1,Patient_Log!F16:F1024))} -> 1
A6: Maximum Interaction Time | B6: {=MAX(IF(Patient_Log!F16:F1024>=1,Patient_Log!F16:F1024))} -> 47.21
A7: Average Interaction Time | B7: =AVERAGEIF(Patient_Log!F16:F1024,"<>0") -> 5.5995607
A9: Total Patients Seen (all time) | B9: =SUM(Unit_Log!E2:E994) -> 461
A11: Session Durations | B11: Minutes
A12: Minimum Duration | B12: {=MIN(IF(Unit_Log!G2:G994>=1,Unit_Log!G2:G994))} -> 1
A13: Maximum Duration | B13: {=MAX(IF(Unit_Log!G8:G994>=1,Unit_Log!G8:G994))} -> 78.23

Sheet Data Dictionary
A1: Column | B1: Description | C1: Type | D1: Notes
A2: Date | B2: Date of visit | C2: Input (YYYY-MM-DD) | D2: Keep format consistent for Power BI
A3: Unit | B3: Patient care unit | C3: Input | D3: 3 West or 2 East
A4: Visit_Window | B4: Time window of visit | C4: Input | D4: 8:00 AM, 11:00 AM, or 2:30 PM
A5: Room | B5: Patient room number | C5: Input
A6: Available | B6: Whether patient was seen | C6: Input | D6: Yes or No
A7: Interaction_Time_Min | B7: Time spent with patient in minutes | C7: Input | D7: Exported from Visit Tracker website; blank if unavailable
A8: Notes | B8: Optional notes per patient | C8: Input | D8: Exported from Visit Tracker website
A9: Unit_Time_Min | B9: Total time spent on that unit including walking | C9: Input | D9: Exported from Visit Tracker website
A10: Combined_Duration_Min | B10: Total time on both units combined | C10: Input | D10: Exported from Visit Tracker website; same value repeats for all rows in a session
A12: POWER BI CALCULATED METRICS
A13: Patients_Attempted | B13: COUNTA of rows per date + unit + visit window | C13: Power BI measure
A14: Patients_Seen | B14: COUNTIF Available = Yes | C14: Power BI measure
A15: Patients_Unavailable | B15: COUNTIF Available = No | C15: Power BI measure
A16: Avg_Interaction_Time_Min | B16: AVERAGE of Interaction_Time_Min per session | C16: Power BI measure
A17: Min_Interaction_Time_Min | B17: MIN of Interaction_Time_Min | C17: Power BI measure
A18: Max_Interaction_Time_Min | B18: MAX of Interaction_Time_Min | C18: Power BI measure
A19: Contact_Rate_Pct | B19: Patients_Seen / Patients_Attempted * 100 | C19: Power BI measure
A24: Reasons for No Visit List
A25: Discharged/Transferred
A26: With Provider
A27: Sleeping/Incapacitated
A28: Not in Room
A29: Isolation/Precaution
A30: Other
